<mujoco model="bumi2.0">
  <compiler angle="radian" meshdir="assets" autolimits="true"/>

    <default>
        <default class="biped">
            <default class="collision">
                <geom group="3" contype="1" conaffinity="1" friction="0.8 0.005 0.0001" rgba="0.804 0.361 0.031 0.5"/>
                <default class="collision_head">
                    <geom type="sphere" size="0.08" pos="0.0 0.0 0.08" rgba="0.804 0.361 0.031 0.5"/>
                </default>

                <default class="collision_base_upper_box">
                    <geom type="box" size="0.08 0.09 0.12" pos="0.0 0.0 0.12" rgba="0.804 0.361 0.031 0.5"/>
                </default>

                <default class="collision_base_lower_box">
                    <geom type="sphere" size="0.08" pos="0.0 0.0 0.0" rgba="0.804 0.361 0.031 0.5"/>
                </default>

                <default class="collision_left_arm_pitch">
                    <geom type="sphere" size="0.04" pos="0.0 0.0 0.0" rgba="0.804 0.361 0.031 0.5"/>
                </default>

                <default class="collision_left_arm_roll">
                    <geom type="sphere" size="0.035" pos="0.0 0.0 0.0" rgba="0.804 0.361 0.031 0.5"/>
                </default>

                <default class="collision_left_arm_yaw">
                    <geom type="sphere" size="0.035" pos="0.0 0.0 0.0" rgba="0.804 0.361 0.031 0.5"/>
                </default>

                <default class="collision_left_elbow_end">
                    <geom type="sphere" size="0.05" pos="0.0 0.0 -0.14" rgba="0.804 0.361 0.031 0.5" />
                </default>

                <default class="collision_right_arm_pitch">
                    <geom type="sphere" size="0.04" pos="0.0 0.0 0.0" rgba="0.804 0.361 0.031 0.5"/>
                </default>

                <default class="collision_right_arm_roll">
                    <geom type="sphere" size="0.035" pos="0.0 0.0 0.0" rgba="0.804 0.361 0.031 0.5"/>
                </default>

                <default class="collision_right_arm_yaw">
                    <geom type="sphere" size="0.035" pos="0.0 0.0 0.0" rgba="0.804 0.361 0.031 0.5"/>
                </default>

                <default class="collision_right_elbow_end">
                    <geom type="sphere" size="0.05" pos="0.0 0.0 -0.14" rgba="0.804 0.361 0.031 0.5"/>
                </default>

                <default class="collision_left_leg_pitch">
                    <geom type="cylinder" size="0.04 0.05" pos="0.0 0.0 0.0" quat="1 0 1 0" rgba="0.804 0.361 0.031 0.5"/>
                </default>

                <default class="collision_left_leg_roll">
                    <geom type="sphere" size="0.038" pos="0.0 0.0 0.0" rgba="0.804 0.361 0.031 0.5"/>
                </default>

                <default class="collision_left_leg_yaw">
                    <geom type="sphere" size="0.038" pos="0.0 0.0 0.0" rgba="0.804 0.361 0.031 0.5"/>
                </default>

                <default class="collision_left_knee">
                    <geom type="sphere" size="0.055" pos="0.0 0.0 0.0" rgba="0.804 0.361 0.031 0.5"/>
                </default>

                <default class="collision_left_ankle">
                    <geom type="box" size="0.09 0.048 0.01" pos="0.0153288 -2.4167e-07 -0.0252579" rgba="0.804 0.361 0.031 0.5"/>
                </default>

                <default class="collision_right_leg_pitch">
                    <geom type="cylinder" size="0.04 0.05" pos="0.0 0.0 0.0" quat="1 0 1 0" rgba="0.804 0.361 0.031 0.5"/>
                </default>

                <default class="collision_right_leg_roll">
                    <geom type="sphere" size="0.038" pos="0.0 0.0 0.0" rgba="0.804 0.361 0.031 0.5"/>
                </default>

                <default class="collision_right_leg_yaw">
                    <geom type="sphere" size="0.038" pos="0.0 0.0 0.0" rgba="0.804 0.361 0.031 0.5"/>
                </default>

                <default class="collision_right_knee">
                    <geom type="sphere" size="0.055" pos="0.0 0.0 0.0" rgba="0.804 0.361 0.031 0.5"/>
                </default>

                <default class="collision_right_ankle">
                    <geom type="box" size="0.09 0.048 0.01" pos="0.0153288 2.4303e-07 -0.0252579" rgba="0.804 0.361 0.031 0.5"/>
                </default>
            </default>

            <default class="visual">
                <geom contype="0" conaffinity="0" group="1"/>
            </default>

            <default class="joint">
                <joint damping="0.001" armature="0.03" frictionloss="0.1"/>
            </default>
        </default>
    </default>

  <asset>

    <mesh name="base_link" file="base_link.STL"/>
    <mesh name="waist_yaw_link" file="waist_yaw_link.STL"/>
    <mesh name="l_arm_pitch_link" file="l_arm_pitch_link.STL"/>
    <mesh name="l_arm_roll_link" file="l_arm_roll_link.STL"/>
    <mesh name="l_arm_yaw_link" file="l_arm_yaw_link.STL"/>
    <mesh name="l_arm_elbow_link" file="l_elbow_pitch_link.STL"/>
    <mesh name="r_arm_pitch_link" file="r_arm_pitch_link.STL"/>
    <mesh name="r_arm_roll_link" file="r_arm_roll_link.STL"/>
    <mesh name="r_arm_yaw_link" file="r_arm_yaw_link.STL"/>
    <mesh name="r_arm_elbow_link" file="r_elbow_pitch_link.STL"/>
    <mesh name="l_leg_pitch_link" file="l_leg_pitch_link.STL"/>
    <mesh name="l_leg_roll_link" file="l_leg_roll_link.STL"/>
    <mesh name="l_leg_yaw_link" file="l_leg_yaw_link.STL"/>
    <mesh name="l_knee_pitch_link" file="l_knee_pitch_link.STL"/>
    <mesh name="l_ankle_pitch_link" file="l_ankle_pitch_link.STL"/>
    <mesh name="l_ankle_roll_link" file="l_ankle_roll_link.STL"/>
    <mesh name="r_leg_pitch_link" file="r_leg_pitch_link.STL"/>
    <mesh name="r_leg_roll_link" file="r_leg_roll_link.STL"/>
    <mesh name="r_leg_yaw_link" file="r_leg_yaw_link.STL"/>
    <mesh name="r_knee_pitch_link" file="r_knee_pitch_link.STL"/>
    <mesh name="r_ankle_pitch_link" file="r_ankle_pitch_link.STL"/>
    <mesh name="r_ankle_roll_link" file="r_ankle_roll_link.STL"/>
  </asset>
  <worldbody>
    <light directional="true" diffuse=".4 .4 .4" specular="0.1 0.1 0.1" pos="0 0 5.0" dir="0 0 -1" castshadow="false"/>
    <light directional="true" diffuse=".6 .6 .6" specular="0.2 0.2 0.2" pos="0 0 4" dir="0 0 -1"/>


    <body name="base_link" pos="0.00000000 0.00000000 0.55">
      <inertial pos="0.000991382 -2.32089e-05 0.0627867" quat="0.70613 0.708074 -0.00268598 0.00216235" mass="2.20073" diaginertia="0.00745362 0.00524716 0.00394619"/>
      <geom type="mesh" contype="0" conaffinity="0" group="1" density="0" rgba="0.79216 0.81961 0.93333 1" mesh="base_link"/>
      <geom class="collision_base_lower_box"/>
      <freejoint name="root" />
      <site name='imu' size='0.01' pos='0.0 0 0.0'/>
      <body name="waist_link" pos="0 0 0.12905">
        <inertial pos="-0.00431433 0.000779481 0.142505" quat="0.999495 0.00366266 0.031287 0.00417016" mass="3.34091" diaginertia="0.0328368 0.0288524 0.0115645"/>
        <joint name="waist_yaw_joint" pos="0 0 0" axis="0 0 1" limited="true" range="-1.57 1.57"/>
        <geom type="mesh" contype="0" conaffinity="0" group="1" density="0" rgba="0.792157 0.819608 0.933333 1" mesh="waist_yaw_link"/>
        <geom class="collision_base_upper_box"/>
        <body name="l_arm_pitch_link" pos="0.0010007 0.083723 0.17204" quat="0.991445 0.130526 0 0">
          <inertial pos="0.00420418 0.0390137 -0.000166374" quat="0.0410242 0.68821 0.0984705 0.717626" mass="0.279302" diaginertia="0.000163107 0.000162095 0.000133594"/>
          <joint name="l_arm_pitch_joint" pos="0 0 0" axis="0 1 0" limited="true" range="-2.36 2.36"/>
          <geom type="mesh" contype="0" conaffinity="0" group="1" density="0" rgba="0.792157 0.819608 0.933333 1" mesh="l_arm_pitch_link"/>
          <geom class="collision_left_arm_pitch"/>
            <body name="l_arm_roll_link" pos="-0.0010007 0.0405 -6.25e-05" quat="0.835969 -0.548777 0 0">
            <inertial pos="-0.000134626 0.0558626 -0.01579" quat="0.606622 0.350291 -0.39486 0.594468" mass="0.352035" diaginertia="0.000485497 0.000433102 0.000227339"/>
            <joint name="l_arm_roll_joint" pos="0 0 0" axis="1 0 0" limited="true" range="-0.14 1.94"/>
            <geom type="mesh" contype="0" conaffinity="0" group="1" density="0" rgba="0.792157 0.819608 0.933333 1" mesh="l_arm_roll_link"/>
            <geom class="collision_left_arm_roll"/>
              <body name="l_arm_yaw_link" pos="0.0010007 0.091512 -0.035515" quat="0.866025 0.500001 0 0">
              <inertial pos="0.00743954 0.00322664 -0.0504594" quat="0.98604 0.0606162 -0.154809 0.00924042" mass="0.309233" diaginertia="0.000221623 0.000207982 0.000139547"/>
              <joint name="l_arm_yaw_joint" pos="0 0 0" axis="0 0 1" limited="true" range="-1.57 1.57"/>
              <geom type="mesh" contype="0" conaffinity="0" group="1" density="0" rgba="0.792157 0.819608 0.933333 1" mesh="l_arm_yaw_link"/>
              <geom class="collision_left_arm_yaw"/>
              <body name="l_arm_elbow_link" pos="0.010308 0 -0.058252">
                <inertial pos="-0.000328283 -0.00070263 -0.071209" quat="0.999251 0.0300514 -0.00936913 0.0224893" mass="0.232041" diaginertia="0.000765092 0.00072886 0.000118734"/>
                <joint name="l_elbow_pitch_joint" pos="0 0 0" axis="0 1 0" limited="true" range="-2.26 0"/>
                <geom type="mesh" contype="0" conaffinity="0" group="1" density="0" rgba="0.792157 0.819608 0.933333 1" mesh="l_arm_elbow_link"/>
                <geom class="collision_left_elbow_end"/>
              </body>
            </body>
          </body>
        </body>
        <body name="r_arm_pitch_link" pos="0.0010007 -0.083723 0.17204" quat="0.991445 -0.130526 0 0">
          <inertial pos="0.00420433 -0.0390135 -0.000165819" quat="-0.0419007 0.688081 -0.0992913 0.717586" mass="0.279308" diaginertia="0.000163109 0.000162099 0.000133598"/>
          <joint name="r_arm_pitch_joint" pos="0 0 0" axis="0 1 0" limited="true" range="-2.36 2.36"/>
          <geom type="mesh" contype="0" conaffinity="0" group="1" density="0" rgba="0.792157 0.819608 0.933333 1" mesh="r_arm_pitch_link"/>
          <geom class="collision_right_arm_pitch"/>
          <body name="r_arm_roll_link" pos="-0.0010007 -0.0405 -6.25e-05" quat="0.835969 0.548777 0 0">
            <inertial pos="-0.000135545 -0.0558642 -0.0157919" quat="0.350291 0.606633 -0.594436 0.39489" mass="0.35202" diaginertia="0.000485461 0.000433064 0.000227333"/>
            <joint name="r_arm_roll_joint" pos="0 0 0" axis="1 0 0" limited="true" range="-0.14 1.94"/>
            <geom type="mesh" contype="0" conaffinity="0" group="1" density="0" rgba="0.792157 0.819608 0.933333 1" mesh="r_arm_roll_link"/>
            <geom class="collision_right_arm_roll"/>
            <body name="r_arm_yaw_link" pos="0.0010007 -0.091512 -0.035515" quat="0.866025 -0.500001 0 0">
              <inertial pos="0.00743969 -0.0032267 -0.05046" quat="0.986041 -0.0606128 -0.154804 -0.0092166" mass="0.309228" diaginertia="0.000221623 0.000207981 0.000139543"/>
              <joint name="r_arm_yaw_joint" pos="0 0 0" axis="0 0 1" limited="true" range="-1.57 1.57"/>
              <geom type="mesh" contype="0" conaffinity="0" group="1" density="0" rgba="0.792157 0.819608 0.933333 1" mesh="r_arm_yaw_link"/>
              <geom class="collision_right_arm_yaw"/>
              <body name="r_arm_elbow_link" pos="0.010308 0 -0.058252">
                <inertial pos="-0.00032911 0.000702748 -0.0712054" quat="0.999253 -0.0300894 -0.00936379 -0.0223874" mass="0.232015" diaginertia="0.000764974 0.000728751 0.000118717"/>
                <joint name="r_elbow_pitch_joint" pos="0 0 0" axis="0 1 0" limited="true" range="-2.26 0"/>
                <geom type="mesh" contype="0" conaffinity="0" group="1" density="0" rgba="0.792157 0.819608 0.933333 1" mesh="r_arm_elbow_link"/>
                <geom class="collision_right_elbow_end"/>
              </body>
            </body>
          </body>
        </body>
      </body>
      <body name="l_leg_pitch_link" pos="-0.011162 0.0468 0.033398">
        <inertial pos="0.0222562 0.0472424 -0.0486573" quat="0.688527 -0.000339392 -0.258913 0.677418" mass="0.888257" diaginertia="0.0015352 0.00120756 0.000908788"/>
        <joint name="l_leg_pitch_joint" pos="0 0 0" axis="0 1 0" limited="true" range="-2.09 2.09"/>
        <geom type="mesh" contype="0" conaffinity="0" group="1" density="0" rgba="0.792157 0.819608 0.933333 1" mesh="l_leg_pitch_link"/>
        <geom class="collision_left_leg_pitch"/>
        <body name="l_leg_roll_link" pos="0.01218 0.053 -0.058648">
          <inertial pos="0.00121237 -3.45164e-05 -0.0685026" quat="0.704806 -0.00727925 -0.00814158 0.709316" mass="0.749492" diaginertia="0.00162101 0.0013376 0.000892224"/>
          <joint name="l_leg_roll_joint" pos="0 0 0" axis="1 0 0" limited="true" range="-0.66 1.57"/>
          <geom type="mesh" contype="0" conaffinity="0" group="1" density="0" rgba="0.792157 0.819608 0.933333 1" mesh="l_leg_roll_link"/>
          <geom class="collision_left_leg_roll"/>
          <body name="l_leg_yaw_link" pos="0 0 -0.1155">
            <inertial pos="0.00265259 0.00636494 -0.0724071" quat="0.983843 0.150006 0.0971645 -0.0104715" mass="0.936643" diaginertia="0.0012577 0.00106213 0.000830318"/>
            <joint name="l_leg_yaw_joint" pos="0 0 0" axis="0 0 1" limited="true" range="-2.53 2.53"/>
            <geom type="mesh" contype="0" conaffinity="0" group="1" density="0" rgba="0.792157 0.819608 0.933333 1" mesh="l_leg_yaw_link"/>
            <geom class="collision_left_leg_yaw"/>
            <body name="l_knee_pitch_link" pos="0 0 -0.0835">
              <inertial pos="0.00690952 -0.00116128 -0.0934036" quat="0.99519 0.0368406 -0.0224839 -0.0879473" mass="1.16909" diaginertia="0.00376841 0.00369425 0.00104565"/>
              <joint name="l_knee_pitch_joint" pos="0 0 0" axis="0 1 0" limited="true" range="0 2.24"/>
              <geom type="mesh" contype="0" conaffinity="0" group="1" density="0" rgba="0.792157 0.819608 0.933333 1" mesh="l_knee_pitch_link"/>
              <geom class="collision_left_knee"/>
              <body name="l_ankle_pitch_link" pos="1.437e-05 0 -0.20237">
                <inertial pos="-0.000133048 0.000877143 0.00133703" quat="0.484301 0.513305 0.480281 0.520866" mass="0.166072" diaginertia="2.96663e-05 2.67576e-05 2.42236e-05"/>
                <joint name="l_ankle_pitch_joint" pos="0 0 0" axis="0 1 0" limited="true" range="-0.96 0.44"/>
                <geom type="mesh" contype="0" conaffinity="0" group="1" density="0" rgba="0.792157 0.819608 0.933333 1" mesh="l_ankle_pitch_link"/>
                <body name="l_ankle_roll_link">
                  <inertial pos="0.0153288 -2.4167e-07 -0.0252579" quat="3.94096e-05 0.727504 -1.18917e-05 0.686103" mass="0.267729" diaginertia="0.000537144 0.000501951 9.62786e-05"/>
                  <joint name="l_ankle_roll_joint" pos="0 0 0" axis="1 0 0" limited="true" range="-0.17 0.17"/>
                  <geom type="mesh" contype="0" conaffinity="0" group="1" density="0" rgba="1 0 0 1" mesh="l_ankle_roll_link"/>
                  <geom class="collision_left_ankle"/>
                </body>
              </body>
            </body>
          </body>
        </body>
      </body>
      <body name="r_leg_pitch_link" pos="-0.011162 -0.0468 0.033398">
        <inertial pos="0.0222551 -0.0472117 -0.0486872" quat="0.678402 -0.25936 -0.000103884 0.687389" mass="0.888269" diaginertia="0.00153471 0.00120749 0.000909896"/>
        <joint name="r_leg_pitch_joint" pos="0 0 0" axis="0 1 0" limited="true" range="-2.09 2.09"/>
        <geom type="mesh" contype="0" conaffinity="0" group="1" density="0" rgba="0.792157 0.819608 0.933333 1" mesh="r_leg_pitch_link"/>
        <geom class="collision_right_leg_pitch"/>
        <body name="r_leg_roll_link" pos="0.01218 -0.053 -0.058648">
          <inertial pos="0.00121108 3.43366e-05 -0.0685066" quat="0.709301 -0.00825784 -0.00733406 0.704819" mass="0.749453" diaginertia="0.00162067 0.0013373 0.000892172"/>
          <joint name="r_leg_roll_joint" pos="0 0 0" axis="1 0 0" limited="true" range="-1.57 0.66"/>
          <geom type="mesh" contype="0" conaffinity="0" group="1" density="0" rgba="0.792157 0.819608 0.933333 1" mesh="r_leg_roll_link"/>
          <geom class="collision_right_leg_roll"/>
          <body name="r_leg_yaw_link" pos="0 0 -0.1155">
            <inertial pos="0.00265208 -0.00636498 -0.0724078" quat="0.983841 -0.150031 0.0971478 0.0104631" mass="0.936613" diaginertia="0.00125765 0.00106208 0.000830292"/>
            <joint name="r_leg_yaw_joint" pos="0 0 0" axis="0 0 1" limited="true" range="-2.53 2.53"/>
            <geom type="mesh" contype="0" conaffinity="0" group="1" density="0" rgba="0.792157 0.819608 0.933333 1" mesh="r_leg_yaw_link"/>
            <geom class="collision_right_leg_yaw"/>
            <body name="r_knee_pitch_link" pos="0 0 -0.0835">
              <inertial pos="0.0069094 0.00116159 -0.093404" quat="0.995194 -0.0368396 -0.0224844 0.0878977" mass="1.16908" diaginertia="0.00376837 0.00369424 0.00104559"/>
              <joint name="r_knee_pitch_joint" pos="0 0 0" axis="0 1 0" limited="true" range="0 2.24"/>
              <geom type="mesh" contype="0" conaffinity="0" group="1" density="0" rgba="0.792157 0.819608 0.933333 1" mesh="r_knee_pitch_link"/>
              <geom class="collision_right_knee"/>
              <body name="r_ankle_pitch_link" pos="1.437e-05 0 -0.20238">
                <inertial pos="-0.000133055 -0.000877143 0.00133704" quat="0.520866 0.480281 0.513305 0.484301" mass="0.166072" diaginertia="2.96663e-05 2.67576e-05 2.42236e-05"/>
                <joint name="r_ankle_pitch_joint" pos="0 0 0" axis="0 1 0" limited="true" range="-0.96 0.44"/>
                <geom type="mesh" contype="0" conaffinity="0" group="1" density="0" rgba="0.792157 0.819608 0.933333 1" mesh="r_ankle_pitch_link"/>
                <body name="r_ankle_roll_link">
                  <inertial pos="0.0153288 2.4303e-07 -0.0252579" quat="-3.94465e-05 0.727504 1.18394e-05 0.686103" mass="0.267729" diaginertia="0.000537144 0.000501951 9.62786e-05"/>
                  <joint name="r_ankle_roll_joint" pos="0 0 0" axis="1 0 0" limited="true" range="-0.17 0.17"/>
                  <geom type="mesh" contype="0" conaffinity="0" group="1" density="0" rgba="1 0 0 1" mesh="r_ankle_roll_link"/>
                  <geom class="collision_right_ankle"/>
                </body>
              </body>
            </body>
          </body>
        </body>
      </body>
    </body>
  </worldbody>



  <sensor>
      <framequat     name='orientation' objtype='site' noise='0.001' objname='imu'/>
      <framepos      name='position' objtype='site' noise='0.001' objname='imu'/>
      <gyro          name='imu_ang_vel'    site='imu' noise='0.005' cutoff='34.9'/>
      <velocimeter   name='imu_lin_vel'     site='imu' noise='0.001' cutoff='30'/>
      <accelerometer name='linear-acceleration' site='imu' noise='0.005' cutoff='157'/>
      <magnetometer  name='magnetometer'        site='imu'/>
  </sensor>
</mujoco>